Traceback (most recent call last):
  File "/home/user/mambaforge/envs/mdd/lib/python3.10/site-packages/jupyter_cache/executors/utils.py", line 58, in single_nb_execution
    executenb(
  File "/home/user/mambaforge/envs/mdd/lib/python3.10/site-packages/nbclient/client.py", line 1305, in execute
    return NotebookClient(nb=nb, resources=resources, km=km, **kwargs).execute()
  File "/home/user/mambaforge/envs/mdd/lib/python3.10/site-packages/jupyter_core/utils/__init__.py", line 173, in wrapped
    return loop.run_until_complete(inner)
  File "/home/user/mambaforge/envs/mdd/lib/python3.10/asyncio/base_events.py", line 649, in run_until_complete
    return future.result()
  File "/home/user/mambaforge/envs/mdd/lib/python3.10/site-packages/nbclient/client.py", line 705, in async_execute
    await self.async_execute_cell(
  File "/home/user/mambaforge/envs/mdd/lib/python3.10/site-packages/nbclient/client.py", line 1058, in async_execute_cell
    await self._check_raise_for_error(cell, cell_index, exec_reply)
  File "/home/user/mambaforge/envs/mdd/lib/python3.10/site-packages/nbclient/client.py", line 914, in _check_raise_for_error
    raise CellExecutionError.from_cell_and_msg(cell, exec_reply_content)
nbclient.exceptions.CellExecutionError: An error occurred while executing the following cell:
------------------
frequency = np.arange(0,f_fold,del_f)  #frequency (Hz)
G = fft.fft(g) # FFT 
Magnitude = np.abs(G)/(N/2.)  #|F|/(N/2)
Magnitude[0] = Magnitude[0]/2
len_loc, = Magnitude.shape
A = Magnitude[0:np.int(round(len_loc/2))]
Freq = frequency[0:np.int(round(len_loc/2))]
------------------


[0;31m---------------------------------------------------------------------------[0m
[0;31mAttributeError[0m                            Traceback (most recent call last)
Cell [0;32mIn[4], line 6[0m
[1;32m      4[0m Magnitude[[38;5;241m0[39m] [38;5;241m=[39m Magnitude[[38;5;241m0[39m][38;5;241m/[39m[38;5;241m2[39m
[1;32m      5[0m len_loc, [38;5;241m=[39m Magnitude[38;5;241m.[39mshape
[0;32m----> 6[0m A [38;5;241m=[39m Magnitude[[38;5;241m0[39m:[43mnp[49m[38;5;241;43m.[39;49m[43mint[49m([38;5;28mround[39m(len_loc[38;5;241m/[39m[38;5;241m2[39m))]
[1;32m      7[0m Freq [38;5;241m=[39m frequency[[38;5;241m0[39m:np[38;5;241m.[39mint([38;5;28mround[39m(len_loc[38;5;241m/[39m[38;5;241m2[39m))]

File [0;32m~/mambaforge/envs/mdd/lib/python3.10/site-packages/numpy/__init__.py:324[0m, in [0;36m__getattr__[0;34m(attr)[0m
[1;32m    319[0m     warnings[38;5;241m.[39mwarn(
[1;32m    320[0m         [38;5;124mf[39m[38;5;124m"[39m[38;5;124mIn the future `np.[39m[38;5;132;01m{[39;00mattr[38;5;132;01m}[39;00m[38;5;124m` will be defined as the [39m[38;5;124m"[39m
[1;32m    321[0m         [38;5;124m"[39m[38;5;124mcorresponding NumPy scalar.[39m[38;5;124m"[39m, [38;5;167;01mFutureWarning[39;00m, stacklevel[38;5;241m=[39m[38;5;241m2[39m)
[1;32m    323[0m [38;5;28;01mif[39;00m attr [38;5;129;01min[39;00m __former_attrs__:
[0;32m--> 324[0m     [38;5;28;01mraise[39;00m [38;5;167;01mAttributeError[39;00m(__former_attrs__[attr])
[1;32m    326[0m [38;5;28;01mif[39;00m attr [38;5;241m==[39m [38;5;124m'[39m[38;5;124mtesting[39m[38;5;124m'[39m:
[1;32m    327[0m     [38;5;28;01mimport[39;00m [38;5;21;01mnumpy[39;00m[38;5;21;01m.[39;00m[38;5;21;01mtesting[39;00m [38;5;28;01mas[39;00m [38;5;21;01mtesting[39;00m

[0;31mAttributeError[0m: module 'numpy' has no attribute 'int'.
`np.int` was a deprecated alias for the builtin `int`. To avoid this error in existing code, use `int` by itself. Doing this will not modify any behavior and is safe. When replacing `np.int`, you may wish to use e.g. `np.int64` or `np.int32` to specify the precision. If you wish to review your current use, check the release note link for additional information.
The aliases was originally deprecated in NumPy 1.20; for more details and guidance see the original release note at:
    https://numpy.org/devdocs/release/1.20.0-notes.html#deprecations

